<?xml version="1.0"?>
<robot name="simple_arm">

  <link name="world"/>

  <!-- all inertia param below set like Izz = (1/12)*(x^2+y^2), that approximately as box
  -->

  <link name="base">
    <collision>
      <origin rpy="0 0 0" xyz="0.0 0.0 0.0"/> 
      <geometry>
        <box size="0.033 0.025 0.033"/>
      </geometry>
    </collision>
    <visual>
      <origin rpy="0 0 0" xyz="0.0 0.0 0.0"/>
      <geometry>
        <box size="0.033 0.025 0.033"/>
      </geometry>
      <material name="white">
        <color rgba="1 1 1 0.5"/>
      </material>
    </visual>
    <inertial>
      <origin rpy="0 0 0" xyz="0 0.0 0"/>
      <mass value="0"/>
      <inertia ixx="0" ixy="0.0" ixz="0.0"
               iyy="0" iyz="0.0"
               izz="0"/>
    </inertial>
  </link>

  <link name="link1">
    <collision>
      <origin rpy="0 0 0" xyz="0 0.017 0.0"/>
      <geometry>
        <box size="0.005 0.034 0.005"/>
      </geometry>
    </collision>
    <visual>
      <origin rpy="0 0 0" xyz="0 0.017 0.0"/>
      <geometry>
        <box size="0.005 0.034 0.005"/>
      </geometry>
      <material name="white">
        <color rgba="1 1 1 0.5"/>
      </material>
    </visual>
    <inertial>
      <origin rpy="0 0 0" xyz="0 0 0"/>
      <mass value="0"/>
      <inertia ixx="0" ixy="0.0" ixz="0.0" 
               iyy="0" iyz="0.0" 
               izz="0"/>
    </inertial>
  </link>

  <link name="link2">
    <collision>
      <origin rpy="0 0 0" xyz="0 0.0 0.0275"/>
      <geometry>
        <box size="0.005 0.005 0.055"/>
      </geometry>
    </collision>
    <visual>
      <origin rpy="0 0 0" xyz="0 0.0 0.0275"/>
      <geometry>
        <box size="0.005 0.005 0.055"/>
      </geometry>
      <material name="gray">
        <color rgba="1 1 1 0.5"/>
      </material>
    </visual>
    <inertial>
      <origin rpy="0 0 0" xyz="0 0 0"/>
      <mass value="0"/>
      <inertia ixx="0" ixy="0.0" ixz="0.0" 
               iyy="0" iyz="0.0" 
               izz="0"/>
    </inertial>
  </link>

  <link name="link3">
    <collision>
      <origin rpy="0 0 0" xyz="0 0.0 0.0115"/>
      <geometry>
        <box size="0.005 0.005 0.023"/>
      </geometry>
    </collision>
    <visual>
      <origin rpy="0 0 0" xyz="0 0.0 0.0115"/>
      <geometry>
        <box size="0.01 0.01 0.023"/>
      </geometry>
      <material name="gray">
        <color rgba="1 1 1 0.5"/>
      </material>
    </visual>
    <inertial>
      <origin rpy="0 0 0" xyz="0 0 0"/>
      <mass value="0.0"/>
      <inertia ixx="0.0" ixy="0.0" ixz="0.0" 
               iyy="0.0" iyz="0.0" 
               izz="0.0"/>
    </inertial>
  </link>

  <link name="link4">
    <collision>
      <origin rpy="0 0 0" xyz="0 0.0 0.0275"/>
      <geometry>
        <box size="0.005 0.005 0.055"/>
      </geometry>
    </collision>
    <visual>
      <origin rpy="0 0 0" xyz="0 0.0 0.0275"/>
      <geometry>
        <box size="0.005 0.005 0.055"/>
      </geometry>
      <material name="gray">
        <color rgba="1 1 1 0.5"/>
      </material>
    </visual>
    <inertial>
      <origin rpy="0 0 0" xyz="0 0 0"/>
      <mass value="0"/>
      <inertia ixx="0.0" ixy="0.0" ixz="0.0" 
               iyy="0.0" iyz="0.0" 
               izz="0.0"/>
    </inertial>
  </link>

  <link name="link5">
    <collision>
      <origin rpy="0 0 0" xyz="0 -0.017 0.0"/>
      <geometry>
        <box size="0.005 0.034 0.005"/>
      </geometry>
    </collision>
    <visual>
      <origin rpy="0 0 0" xyz="0 -0.017 0.0"/>
      <geometry>
        <box size="0.005 0.034 0.005"/>
      </geometry>
      <material name="gray">
        <color rgba="1 1 1 0.5"/>
      </material>
    </visual>
    <inertial>
      <origin rpy="0 0 0" xyz="0 0 0"/>
      <mass value="0"/>
      <inertia ixx="0.0" ixy="0.0" ixz="0.0" 
               iyy="0.0" iyz="0.0" 
               izz="0.0"/>
    </inertial>
  </link>

  <link name="link6">
    <collision>
      <origin rpy="0 0 0" xyz="0 0 0.0165"/>
      <geometry>
        <box size="0.005 0.005 0.033"/>
      </geometry>
    </collision>
    <visual>
      <origin rpy="0 0 0" xyz="0 0 0.0165"/>
      <geometry>
        <box size="0.005 0.005 0.033"/>
      </geometry>
      <material name="gray">
        <color rgba="1 1 1 0.5"/>
      </material>
    </visual>
    <inertial>
      <origin rpy="0 0 0" xyz="0 0 0"/>
      <mass value="0"/>
      <inertia ixx="0.0" ixy="0.0" ixz="0.0" 
               iyy="0.0" iyz="0.0" 
               izz="0.0"/>
    </inertial>
  </link>

  <link name="link7">
    <collision>
      <origin rpy="0 0 0" xyz="0 0.02 0.0"/>
      <geometry>
        <box size="0.005 0.04 0.005"/>
      </geometry>
    </collision>
    <visual>
      <origin rpy="0 0 0" xyz="0 0.02 0.0"/>
      <geometry>
        <box size="0.005 0.04 0.005"/>
      </geometry>
      <material name="gray">
        <color rgba="1 1 1 0.5"/>
      </material>
    </visual>
    <inertial>
      <origin rpy="0 0 0" xyz="0 0 0"/>
      <mass value="0"/>
      <inertia ixx="0.0" ixy="0.0" ixz="0.0" 
               iyy="0.0" iyz="0.0" 
               izz="0.0"/>
    </inertial>
  </link>

  <joint name="fixed" type="fixed">
    <parent link="world"/>
    <child link="base"/>
  </joint>

  <joint name="joint1" type="revolute">
    <parent link="base"/>
    <child link="link1"/>
    <axis xyz="0 1 0 "/>
    <origin rpy="0 0 0" xyz="0.0 0.0 0.0"/>
    <limit effort="10000" lower="-1.57" upper="1.57" velocity="0.5"/>
  </joint>

  <joint name="joint2" type="revolute">
    <parent link="link1"/>
    <child link="link2"/>
    <axis xyz="1 0 0"/>
    <origin rpy="0 0 0" xyz="0 0.034 0.0"/>
    <limit effort="10000" lower="-0.52" upper="1.57" velocity="0.5"/>
  </joint>

  <joint name="joint3" type="revolute">
    <parent link="link2"/>
    <child link="link3"/>
    <axis xyz="1 0 0"/>
    <origin rpy="0 0 0" xyz="0 0.0 0.055"/>
    <limit effort="10000" lower="-1.57" upper="1.57" velocity="0.5"/>
  </joint>

  <joint name="joint4" type="revolute">
    <parent link="link3"/>
    <child link="link4"/>
    <axis xyz="1 0 0"/>
    <origin rpy="0 0 0" xyz="0 0.0 0.023"/>
    <limit effort="10000" lower="-1.57" upper="1.57" velocity="0.5"/>
  </joint>

  <joint name="joint5" type="revolute">
    <parent link="link4"/>
    <child link="link5"/>
    <axis xyz="1 0 0"/>
    <origin rpy="0 0 0" xyz="0 0.0 0.055"/>
    <limit effort="10000" lower="-0.785" upper="0" velocity="0.5"/>
  </joint>

  <joint name="joint6" type="revolute">
    <parent link="link5"/>
    <child link="link6"/>
    <axis xyz="0 1 0"/>
    <origin rpy="0 0 0" xyz="0 -0.034 0.0"/>
    <limit effort="10000" lower="-1.57" upper="1.57" velocity="0.5"/>
  </joint>

  <joint name="joint7" type="fixed">
    <parent link="link6"/>
    <child link="link7"/>
    <axis xyz="0 1 0"/>
    <origin rpy="0 0 0" xyz="0 0.0 0.033"/>
  </joint>

  <gazebo>
    <plugin name="gazebo_ros_control" filename="libgazebo_ros_control.so">
      <robotNamespace>/simple_arm</robotNamespace>
      <robotSimType>gazebo_ros_control/DefaultRobotHWSim</robotSimType>
    </plugin>
  </gazebo>

  <transmission name="tran1">
    <type>transmission_interface/SimpleTransmission</type>
    <joint name="joint1">
      <hardwareInterface>EffortJointInterface</hardwareInterface>
    </joint>
    <actuator name="motor1">
      <hardwareInterface>EffortJointInterface</hardwareInterface>
      <mechanicalReduction>1</mechanicalReduction>
    </actuator>
  </transmission>
  <transmission name="tran2">
    <type>transmission_interface/SimpleTransmission</type>
    <joint name="joint2">
      <hardwareInterface>EffortJointInterface</hardwareInterface>
    </joint>
    <actuator name="motor2">
      <hardwareInterface>EffortJointInterface</hardwareInterface>
      <mechanicalReduction>1</mechanicalReduction>
    </actuator>
  </transmission>
  <transmission name="tran3">
    <type>transmission_interface/SimpleTransmission</type>
    <joint name="joint3">
      <hardwareInterface>EffortJointInterface</hardwareInterface>
    </joint>
    <actuator name="motor3">
      <hardwareInterface>EffortJointInterface</hardwareInterface>
      <mechanicalReduction>1</mechanicalReduction>
    </actuator>
  </transmission>
  <transmission name="tran4">
    <type>transmission_interface/SimpleTransmission</type>
    <joint name="joint4">
      <hardwareInterface>EffortJointInterface</hardwareInterface>
    </joint>
    <actuator name="motor4">
      <hardwareInterface>EffortJointInterface</hardwareInterface>
      <mechanicalReduction>1</mechanicalReduction>
    </actuator>
  </transmission>
  <transmission name="tran5">
    <type>transmission_interface/SimpleTransmission</type>
    <joint name="joint5">
      <hardwareInterface>EffortJointInterface</hardwareInterface>
    </joint>
    <actuator name="motor5">
      <hardwareInterface>EffortJointInterface</hardwareInterface>
      <mechanicalReduction>1</mechanicalReduction>
    </actuator>
  </transmission>


</robot>
